Workbook

Sheet Cover
C1: AMIR J
C4: TESLA, INC. (NASDAQ: TSLA)
C6: Applied DCF Valuation Model
C7: Valuation date: 30 June 2026 | All figures in USD millions unless stated
C11: Table of Contents
C13: Outputs
C14: Inputs
C15: Model
C22: Colour Convention
C23: Blue: hardcoded input | H23: Yellow fill marks key assumptions and headline outputs.
C24: Black: formula
C25: Green: link to another worksheet
C29: Primary Source
C30: Tesla Q4 and FY2025 Update and Q2 2026 Update, Tesla Investor Relations, ir.tesla.com
C31: Bloomberg (2026) Bloomberg Terminal. Bloomberg L.P.

Sheet Outputs
C1: AMIR J
C5: Dashboard: Perpetuity Growth Method
E8: Model Drivers Set To | G8: 2 | M8: All figures in USD millions unless stated
E11: Main Outputs | M11: Selected Inputs
G13: Enterprise | H13: Equity | I13: Equity
E14: Live (Current Switch) | G14: Value | H14: Value | I14: Per Share | M14: Terminal Growth Rate | P14: =Inputs!$G$142 -> 0.03
G15: =Model!$I$307 -> 616187.58 | H15: =G15-$P$16 -> 651870.58 | I15: =H15/$P$17 -> 183.88451 | M15: WACC | P15: =Inputs!$M$122 -> 0.078316088
E16: Best Case | F16: 1 | G16: 1443710.8 | H16: =G16-$P$16 -> 1479393.8 | I16: =H16/$P$17 -> 417.31841 | M16: Net Debt / (Net Cash) | O16: (End of 2025) | P16: =Inputs!$M$132 -> -35683
E17: Base Case | F17: 2 | G17: 616187.58 | H17: =G17-$P$16 -> 651870.58 | I17: =H17/$P$17 -> 183.88451 | M17: Shares Outstanding | O17: (FD, m) | P17: =Inputs!$G$140 -> 3545
E18: Worst Case | F18: 3 | G18: 181365.43 | H18: =G18-$P$16 -> 217048.43 | I18: =H18/$P$17 -> 61.226639 | M18: Current Share Price | O18: (US$/sh) | P18: =Inputs!$G$141 -> 309.22
E22: Enterprise Value | M22: Equity Value per Share
E24: Terminal Growth Rate | M24: Terminal Growth Rate
D25: =Model!$I$307 -> 616187.58 | E25: =F25-0.005 -> 0.02 | F25: =G25-0.005 -> 0.025 | G25: =Inputs!$G$142 -> 0.03 | H25: =G25+0.005 -> 0.035 | I25: =H25+0.005 -> 0.04 | M25: =E25 -> 0.02 | N25: =F25 -> 0.025 | O25: =G25 -> 0.03 | P25: =H25 -> 0.035 | Q25: =I25 -> 0.04
C26: WACC | D26: =D27-0.005 -> 0.068316088 | E26: 669146.16 | F26: 727940.16 | G26: 802078.62 | H26: 898470.14 | I26: 1028902.9 | K26: WACC | L26: =D26 -> 0.068316088 | M26: =E39/$P$17 -> 198.82346 | N26: =F39/$P$17 -> 215.40851 | O26: =G39/$P$17 -> 236.32204 | P26: =H39/$P$17 -> 263.51287 | Q26: =I39/$P$17 -> 300.30632
D27: =D28-0.005 -> 0.073316088 | E27: 596351.68 | F27: 642045.68 | G27: 698288.65 | H27: 769210.3 | I27: 861419.45 | L27: =D27 -> 0.073316088 | M27: =E40/$P$17 -> 178.28905 | N27: =F40/$P$17 -> 191.17875 | O27: =G40/$P$17 -> 207.04419 | P27: =H40/$P$17 -> 227.0503 | Q27: =I40/$P$17 -> 253.06134
D28: =Inputs!$M$122 -> 0.078316088 | E28: 536243.95 | F28: 572467.19 | G28: 616187.58 | H28: 670001.29 | I28: 737859.69 | L28: =D28 -> 0.078316088 | M28: =E41/$P$17 -> 161.33341 | N28: =F41/$P$17 -> 171.55154 | O28: =G41/$P$17 -> 183.88451 | P28: =H41/$P$17 -> 199.06468 | Q28: =I41/$P$17 -> 218.20668
D29: =D28+0.005 -> 0.083316088 | E29: 485811.69 | F29: 515002.42 | G29: 549668.19 | H29: 591508.74 | I29: 643008.65 | L29: =D29 -> 0.083316088 | M29: =E42/$P$17 -> 147.10711 | N29: =F42/$P$17 -> 155.34145 | O29: =G42/$P$17 -> 165.12022 | P29: =H42/$P$17 -> 176.92292 | Q29: =I42/$P$17 -> 191.45039
D30: =D29+0.005 -> 0.088316088 | E30: 442925.39 | F30: 466776.67 | G30: 494717.95 | H30: 527899.92 | I30: 567949.58 | L30: =D30 -> 0.088316088 | M30: =E43/$P$17 -> 135.00942 | N30: =F43/$P$17 -> 141.73757 | O30: =G43/$P$17 -> 149.61945 | P30: =H43/$P$17 -> 158.97967 | Q30: =I43/$P$17 -> 170.27717
E35: Equity Value | M35: Premium / (Discount) to Share Price
E37: Terminal Growth Rate | M37: Terminal Growth Rate
E38: =E25 -> 0.02 | F38: =F25 -> 0.025 | G38: =G25 -> 0.03 | H38: =H25 -> 0.035 | I38: =I25 -> 0.04 | M38: =E38 -> 0.02 | N38: =F38 -> 0.025 | O38: =G38 -> 0.03 | P38: =H38 -> 0.035 | Q38: =I38 -> 0.04
C39: WACC | D39: =D40-0.005 -> 0.068316088 | E39: =E26-$P$16 -> 704829.16 | F39: =F26-$P$16 -> 763623.16 | G39: =G26-$P$16 -> 837761.62 | H39: =H26-$P$16 -> 934153.14 | I39: =I26-$P$16 -> 1064585.9 | K39: WACC | L39: =D39 -> 0.068316088 | M39: =M26/$P$18-1 -> -0.35701618 | N39: =N26/$P$18-1 -> -0.30338107 | O39: =O26/$P$18-1 -> -0.23574789 | P39: =P26/$P$18-1 -> -0.14781426 | Q39: =Q26/$P$18-1 -> -0.028826332
D40: =D41-0.005 -> 0.073316088 | E40: =E27-$P$16 -> 632034.68 | F40: =F27-$P$16 -> 677728.68 | G40: =G27-$P$16 -> 733971.65 | H40: =H27-$P$16 -> 804893.3 | I40: =I27-$P$16 -> 897102.45 | L40: =D40 -> 0.073316088 | M40: =M27/$P$18-1 -> -0.42342329 | N40: =N27/$P$18-1 -> -0.38173872 | O40: =O27/$P$18-1 -> -0.3304308 | P40: =P27/$P$18-1 -> -0.26573218 | Q40: =Q27/$P$18-1 -> -0.18161393
D41: =D28 -> 0.078316088 | E41: =E28-$P$16 -> 571926.95 | F41: =F28-$P$16 -> 608150.19 | G41: =G28-$P$16 -> 651870.58 | H41: =H28-$P$16 -> 705684.29 | I41: =I28-$P$16 -> 773542.69 | L41: =D41 -> 0.078316088 | M41: =M28/$P$18-1 -> -0.47825686 | N41: =N28/$P$18-1 -> -0.44521203 | O41: =O28/$P$18-1 -> -0.4053279 | P41: =P28/$P$18-1 -> -0.35623608 | Q41: =Q28/$P$18-1 -> -0.29433193
D42: =D41+0.005 -> 0.083316088 | E42: =E29-$P$16 -> 521494.69 | F42: =F29-$P$16 -> 550685.42 | G42: =G29-$P$16 -> 585351.19 | H42: =H29-$P$16 -> 627191.74 | I42: =I29-$P$16 -> 678691.65 | L42: =D42 -> 0.083316088 | M42: =M29/$P$18-1 -> -0.52426394 | N42: =N29/$P$18-1 -> -0.49763455 | O42: =O29/$P$18-1 -> -0.46601054 | P42: =P29/$P$18-1 -> -0.42784129 | Q42: =Q29/$P$18-1 -> -0.38086025
D43: =D42+0.005 -> 0.088316088 | E43: =E30-$P$16 -> 478608.39 | F43: =F30-$P$16 -> 502459.67 | G43: =G30-$P$16 -> 530400.95 | H43: =H30-$P$16 -> 563582.92 | I43: =I30-$P$16 -> 603632.58 | L43: =D43 -> 0.088316088 | M43: =M30/$P$18-1 -> -0.56338718 | N43: =N30/$P$18-1 -> -0.54162873 | O43: =O30/$P$18-1 -> -0.51613915 | P43: =P30/$P$18-1 -> -0.48586874 | Q43: =Q30/$P$18-1 -> -0.44933325
C47: Dashboard: Terminal Multiple Method
M49: All figures in USD millions unless stated
E52: Main Outputs | M52: Selected Inputs
G54: Enterprise | H54: Equity | I54: Equity
E55: Live (Current Switch) | G55: Value | H55: Value | I55: Per Share | M55: Terminal EBITDA Multiple | P55: =Inputs!$G$143 -> 12
G56: =Model!$I$349 -> 589784.74 | H56: =G56-$P$57 -> 625467.74 | I56: =H56/$P$58 -> 176.4366 | M56: WACC | P56: =Inputs!$M$122 -> 0.078316088
E57: Best Case | F57: 1 | G57: 1252716.2 | H57: =G57-$P$57 -> 1288399.2 | I57: =H57/$P$58 -> 363.44124 | M57: Net Debt / (Net Cash) | O57: (End of 2025) | P57: =Inputs!$M$132 -> -35683
E58: Base Case | F58: 2 | G58: 589784.74 | H58: =G58-$P$57 -> 625467.74 | I58: =H58/$P$58 -> 176.4366 | M58: Shares Outstanding | O58: (FD, m) | P58: =Inputs!$G$140 -> 3545
E59: Worst Case | F59: 3 | G59: 223616.16 | H59: =G59-$P$57 -> 259299.16 | I59: =H59/$P$58 -> 73.145037 | M59: Current Share Price | O59: (US$/sh) | P59: =Inputs!$G$141 -> 309.22
E63: Enterprise Value | M63: Equity Value per Share
E65: Terminal EBITDA Multiple | M65: Terminal EBITDA Multiple
D66: =Model!$I$349 -> 589784.74 | E66: =F66-0.5 -> 11 | F66: =G66-0.5 -> 11.5 | G66: =Inputs!$G$143 -> 12 | H66: =G66+0.5 -> 12.5 | I66: =H66+0.5 -> 13 | M66: =E66 -> 11 | N66: =F66 -> 11.5 | O66: =G66 -> 12 | P66: =H66 -> 12.5 | Q66: =I66 -> 13
C67: WACC | D67: =D68-0.005 -> 0.068316088 | E67: 600258.26 | F67: 620279.05 | G67: 640299.83 | H67: 660320.62 | I67: 680341.41 | K67: WACC | L67: =D67 -> 0.068316088 | M67: =E80/$P$58 -> 179.39105 | N67: =F80/$P$58 -> 185.03866 | O67: =G80/$P$58 -> 190.68627 | P67: =H80/$P$58 -> 196.33388 | Q67: =I80/$P$58 -> 201.9815
D68: =D69-0.005 -> 0.073316088 | E68: 576146.78 | F68: 595298.88 | G68: 614450.98 | H68: 633603.08 | I68: 652755.17 | L68: =D68 -> 0.073316088 | M68: =E81/$P$58 -> 172.5895 | N68: =F81/$P$58 -> 177.99207 | O68: =G81/$P$58 -> 183.39463 | P68: =H81/$P$58 -> 188.7972 | Q68: =I81/$P$58 -> 194.19977
...

Sheet Inputs
C1: AMIR J
C7: Scenario Drivers
C9: All figures in USD millions unless stated
C11: Driver switch | E11: =Outputs!G8 -> 2
G13: Forecast | H13: 2026 | I13: 2027 | J13: 2028 | K13: 2029 | L13: 2030 | M13: 2031 | N13: 2032 | O13: 2033 | P13: 2034 | Q13: 2035 | R13: Term
C16: Vehicle Deliveries Growth | H16: =INDEX(H17:H19,$E$11) -> 0.13 | I16: =INDEX(I17:I19,$E$11) -> 0.1 | J16: =INDEX(J17:J19,$E$11) -> 0.09 | K16: =INDEX(K17:K19,$E$11) -> 0.08 | L16: =INDEX(L17:L19,$E$11) -> 0.07 | M16: =INDEX(M17:M19,$E$11) -> 0.06 | N16: =INDEX(N17:N19,$E$11) -> 0.055 | O16: =INDEX(O17:O19,$E$11) -> 0.05 | ... R16: =INDEX(R17:R19,$E$11) -> 0.03
C17: Best Case | H17: 0.16 | I17: 0.14 | J17: 0.13 | K17: 0.12 | L17: 0.11 | M17: 0.09 | N17: 0.08 | O17: 0.07 | P17: 0.06 | Q17: 0.05 | R17: 0.035
C18: Base Case | H18: 0.13 | I18: 0.1 | J18: 0.09 | K18: 0.08 | L18: 0.07 | M18: 0.06 | N18: 0.055 | O18: 0.05 | P18: 0.04 | Q18: 0.035 | R18: 0.03
C19: Worst Case | H19: 0.09 | I19: 0.05 | J19: 0.04 | K19: 0.035 | L19: 0.03 | M19: 0.03 | N19: 0.025 | O19: 0.02 | P19: 0.02 | Q19: 0.02 | R19: 0.02
C22: Average Selling Price Change | H22: =INDEX(H23:H25,$E$11) -> -0.02 | I22: =INDEX(I23:I25,$E$11) -> -0.015 | J22: =INDEX(J23:J25,$E$11) -> -0.01 | K22: =INDEX(K23:K25,$E$11) -> -0.005 | L22: =INDEX(L23:L25,$E$11) -> 0 | M22: =INDEX(M23:M25,$E$11) -> 0.005 | N22: =INDEX(N23:N25,$E$11) -> 0.005 | O22: =INDEX(O23:O25,$E$11) -> 0.01 | ... R22: =INDEX(R23:R25,$E$11) -> 0.01
C23: Best Case | H23: -0.01 | I23: 0 | J23: 0.005 | K23: 0.01 | L23: 0.01 | M23: 0.01 | N23: 0.01 | O23: 0.015 | P23: 0.015 | Q23: 0.015 | R23: 0.015
C24: Base Case | H24: -0.02 | I24: -0.015 | J24: -0.01 | K24: -0.005 | L24: 0 | M24: 0.005 | N24: 0.005 | O24: 0.01 | P24: 0.01 | Q24: 0.01 | R24: 0.01
C25: Worst Case | H25: -0.04 | I25: -0.03 | J25: -0.02 | K25: -0.015 | L25: -0.01 | M25: -0.005 | N25: 0 | O25: 0 | P25: 0.005 | Q25: 0.005 | R25: 0.005
C28: Energy Revenue Growth | H28: =INDEX(H29:H31,$E$11) -> 0.18 | I28: =INDEX(I29:I31,$E$11) -> 0.33 | J28: =INDEX(J29:J31,$E$11) -> 0.22 | K28: =INDEX(K29:K31,$E$11) -> 0.18 | L28: =INDEX(L29:L31,$E$11) -> 0.15 | M28: =INDEX(M29:M31,$E$11) -> 0.13 | N28: =INDEX(N29:N31,$E$11) -> 0.11 | O28: =INDEX(O29:O31,$E$11) -> 0.09 | ... R28: =INDEX(R29:R31,$E$11) -> 0.05
C29: Best Case | H29: 0.29 | I29: 0.4 | J29: 0.31 | K29: 0.23 | L29: 0.2 | M29: 0.17 | N29: 0.14 | O29: 0.12 | P29: 0.1 | Q29: 0.08 | R29: 0.06
C30: Base Case | H30: 0.18 | I30: 0.33 | J30: 0.22 | K30: 0.18 | L30: 0.15 | M30: 0.13 | N30: 0.11 | O30: 0.09 | P30: 0.07 | Q30: 0.06 | R30: 0.05
C31: Worst Case | H31: 0.15 | I31: 0.16 | J31: 0.13 | K31: 0.1 | L31: 0.08 | M31: 0.07 | N31: 0.06 | O31: 0.05 | P31: 0.04 | Q31: 0.04 | R31: 0.035
C34: Services & Software Revenue Growth | H34: =INDEX(H35:H37,$E$11) -> 0.3 | I34: =INDEX(I35:I37,$E$11) -> 0.19 | J34: =INDEX(J35:J37,$E$11) -> 0.3 | K34: =INDEX(K35:K37,$E$11) -> 0.28 | L34: =INDEX(L35:L37,$E$11) -> 0.25 | M34: =INDEX(M35:M37,$E$11) -> 0.2 | N34: =INDEX(N35:N37,$E$11) -> 0.16 | O34: =INDEX(O35:O37,$E$11) -> 0.13 | ... R34: =INDEX(R35:R37,$E$11) -> 0.05
C35: Best Case | H35: 0.35 | I35: 0.28 | J35: 0.42 | K35: 0.38 | L35: 0.33 | M35: 0.27 | N35: 0.22 | O35: 0.18 | P35: 0.14 | Q35: 0.11 | R35: 0.06
C36: Base Case | H36: 0.3 | I36: 0.19 | J36: 0.3 | K36: 0.28 | L36: 0.25 | M36: 0.2 | N36: 0.16 | O36: 0.13 | P36: 0.1 | Q36: 0.08 | R36: 0.05
C37: Worst Case | H37: 0.16 | I37: 0.15 | J37: 0.14 | K37: 0.12 | L37: 0.1 | M37: 0.09 | N37: 0.08 | O37: 0.07 | P37: 0.06 | Q37: 0.05 | R37: 0.04
C40: Automotive Gross Margin (excl. D&A) | H40: =INDEX(H41:H43,$E$11) -> 0.18 | I40: =INDEX(I41:I43,$E$11) -> 0.19 | J40: =INDEX(J41:J43,$E$11) -> 0.25 | K40: =INDEX(K41:K43,$E$11) -> 0.255 | L40: =INDEX(L41:L43,$E$11) -> 0.26 | M40: =INDEX(M41:M43,$E$11) -> 0.265 | N40: =INDEX(N41:N43,$E$11) -> 0.27 | O40: =INDEX(O41:O43,$E$11) -> 0.27 | ... R40: =INDEX(R41:R43,$E$11) -> 0.275
C41: Best Case | H41: 0.23 | I41: 0.265 | J41: 0.275 | K41: 0.285 | L41: 0.29 | M41: 0.295 | N41: 0.3 | O41: 0.3 | P41: 0.305 | Q41: 0.305 | R41: 0.305
C42: Base Case | H42: 0.18 | I42: 0.19 | J42: 0.25 | K42: 0.255 | L42: 0.26 | M42: 0.265 | N42: 0.27 | O42: 0.27 | P42: 0.275 | Q42: 0.275 | R42: 0.275
C43: Worst Case | H43: 0.15 | I43: 0.17 | J43: 0.225 | K43: 0.23 | L43: 0.235 | M43: 0.24 | N43: 0.24 | O43: 0.245 | P43: 0.245 | Q43: 0.245 | R43: 0.245
C46: Energy Gross Margin (excl. D&A) | H46: =INDEX(H47:H49,$E$11) -> 0.29 | I46: =INDEX(I47:I49,$E$11) -> 0.29 | J46: =INDEX(J47:J49,$E$11) -> 0.34 | K46: =INDEX(K47:K49,$E$11) -> 0.35 | L46: =INDEX(L47:L49,$E$11) -> 0.35 | M46: =INDEX(M47:M49,$E$11) -> 0.35 | N46: =INDEX(N47:N49,$E$11) -> 0.35 | O46: =INDEX(O47:O49,$E$11) -> 0.35 | ... R46: =INDEX(R47:R49,$E$11) -> 0.35
C47: Best Case | H47: 0.35 | I47: 0.36 | J47: 0.37 | K47: 0.38 | L47: 0.38 | M47: 0.38 | N47: 0.38 | O47: 0.38 | P47: 0.38 | Q47: 0.38 | R47: 0.38
C48: Base Case | H48: 0.29 | I48: 0.29 | J48: 0.34 | K48: 0.35 | L48: 0.35 | M48: 0.35 | N48: 0.35 | O48: 0.35 | P48: 0.35 | Q48: 0.35 | R48: 0.35
C49: Worst Case | H49: 0.26 | I49: 0.25 | J49: 0.3 | K49: 0.3 | L49: 0.3 | M49: 0.3 | N49: 0.3 | O49: 0.3 | P49: 0.3 | Q49: 0.3 | R49: 0.3
C52: Services & Software Gross Margin (excl. D&A) | H52: =INDEX(H53:H55,$E$11) -> 0.12 | I52: =INDEX(I53:I55,$E$11) -> 0.12 | J52: =INDEX(J53:J55,$E$11) -> 0.26 | K52: =INDEX(K53:K55,$E$11) -> 0.31 | L52: =INDEX(L53:L55,$E$11) -> 0.35 | M52: =INDEX(M53:M55,$E$11) -> 0.38 | N52: =INDEX(N53:N55,$E$11) -> 0.4 | O52: =INDEX(O53:O55,$E$11) -> 0.41 | ... R52: =INDEX(R53:R55,$E$11) -> 0.42
C53: Best Case | H53: 0.16 | I53: 0.23 | J53: 0.34 | K53: 0.4 | L53: 0.45 | M53: 0.48 | N53: 0.5 | O53: 0.51 | P53: 0.52 | Q53: 0.52 | R53: 0.52
C54: Base Case | H54: 0.12 | I54: 0.12 | J54: 0.26 | K54: 0.31 | L54: 0.35 | M54: 0.38 | N54: 0.4 | O54: 0.41 | P54: 0.42 | Q54: 0.42 | R54: 0.42
C55: Worst Case | H55: 0.1 | I55: 0.1 | J55: 0.18 | K55: 0.21 | L55: 0.23 | M55: 0.25 | N55: 0.26 | O55: 0.27 | P55: 0.28 | Q55: 0.28 | R55: 0.28
C58: Operating Expense Growth (excl. D&A) | H58: =INDEX(H59:H61,$E$11) -> 0.22 | I58: =INDEX(I59:I61,$E$11) -> 0.15 | J58: =INDEX(J59:J61,$E$11) -> 0.12 | K58: =INDEX(K59:K61,$E$11) -> 0.1 | L58: =INDEX(L59:L61,$E$11) -> 0.08 | M58: =INDEX(M59:M61,$E$11) -> 0.07 | N58: =INDEX(N59:N61,$E$11) -> 0.06 | O58: =INDEX(O59:O61,$E$11) -> 0.06 | ... R58: =INDEX(R59:R61,$E$11) -> 0.04
C59: Best Case | H59: 0.18 | I59: 0.12 | J59: 0.1 | K59: 0.08 | L59: 0.07 | M59: 0.06 | N59: 0.05 | O59: 0.05 | P59: 0.045 | Q59: 0.045 | R59: 0.035
C60: Base Case | H60: 0.22 | I60: 0.15 | J60: 0.12 | K60: 0.1 | L60: 0.08 | M60: 0.07 | N60: 0.06 | O60: 0.06 | P60: 0.05 | Q60: 0.05 | R60: 0.04
C61: Worst Case | H61: 0.2 | I61: 0.12 | J61: 0.08 | K61: 0.06 | L61: 0.05 | M61: 0.04 | N61: 0.04 | O61: 0.035 | P61: 0.03 | Q61: 0.03 | R61: 0.025
C64: Capital Expenditure | H64: =INDEX(H65:H67,$E$11) -> 24000 | I64: =INDEX(I65:I67,$E$11) -> 17000 | J64: =INDEX(J65:J67,$E$11) -> 15000 | K64: =INDEX(K65:K67,$E$11) -> 14000 | L64: =INDEX(L65:L67,$E$11) -> 13500 | M64: =INDEX(M65:M67,$E$11) -> 13500 | N64: =INDEX(N65:N67,$E$11) -> 14000 | O64: =INDEX(O65:O67,$E$11) -> 14500 | ... R64: =INDEX(R65:R67,$E$11) -> 15269.75
C65: Best Case | H65: 20000 | I65: 16000 | J65: 14000 | K65: 13000 | L65: 12500 | M65: 12500 | N65: 13000 | O65: 13500 | P65: 14000 | Q65: 14500 | R65: =Model!$T$121 -> 15269.75
C66: Base Case | H66: 24000 | I66: 17000 | J66: 15000 | K66: 14000 | L66: 13500 | M66: 13500 | N66: 14000 | O66: 14500 | P66: 15000 | Q66: 15500 | R66: =Model!$T$121 -> 15269.75
...

Sheet Model
C1: AMIR J
C8: Revenue Schedule
C10: All figures in USD millions unless stated | G10: 2023 | H10: 2024 | I10: 2025 | J10: =Inputs!H$13 -> 2026 | K10: =Inputs!I$13 -> 2027 | L10: =Inputs!J$13 -> 2028 | M10: =Inputs!K$13 -> 2029 | N10: =Inputs!L$13 -> 2030 | O10: =Inputs!M$13 -> 2031 | P10: =Inputs!N$13 -> 2032 | Q10: =Inputs!O$13 -> 2033 | ... S10: =Inputs!Q$13 -> 2035 | T10: Term
C11: =IF(Inputs!$E$11=1,"Best Case Selected",IF(Inputs!$E$11=2,"Base Case Selected","Worst Case Selected")) -> Base Case Selected
C13: Vehicle Deliveries Growth | H13: =H14/G14-1 -> -0.01070176 | I13: =I14/H14-1 -> -0.085566049 | J13: =Inputs!H16 -> 0.13 | K13: =Inputs!I16 -> 0.1 | L13: =Inputs!J16 -> 0.09 | M13: =Inputs!K16 -> 0.08 | N13: =Inputs!L16 -> 0.07 | O13: =Inputs!M16 -> 0.06 | P13: =Inputs!N16 -> 0.055 | Q13: =Inputs!O16 -> 0.05 | ... T13: =Inputs!R16 -> 0.03
C14: Vehicle Deliveries | E14: (Units) | G14: 1808581 | H14: 1789226 | I14: 1636129 | J14: =I14*(1+J13) -> 1848825.8 | K14: =J14*(1+K13) -> 2033708.3 | L14: =K14*(1+L13) -> 2216742.1 | M14: =L14*(1+M13) -> 2394081.5 | N14: =M14*(1+N13) -> 2561667.2 | O14: =N14*(1+O13) -> 2715367.2 | P14: =O14*(1+P13) -> 2864712.4 | Q14: =P14*(1+Q13) -> 3007948 | ... T14: =S14*(1+T13) -> 3334887.9
C16: Average Selling Price Change | H16: =H17/G17-1 -> -0.054784615 | I16: =I17/H17-1 -> -0.013471711 | J16: =Inputs!H22 -> -0.02 | K16: =Inputs!I22 -> -0.015 | L16: =Inputs!J22 -> -0.01 | M16: =Inputs!K22 -> -0.005 | N16: =Inputs!L22 -> 0 | O16: =Inputs!M22 -> 0.005 | P16: =Inputs!N22 -> 0.005 | Q16: =Inputs!O22 -> 0.01 | ... T16: =Inputs!R22 -> 0.01
C17: Average Selling Price | E17: (USD/Unit) | G17: =G19*1000000/G14 -> 45571.086 | H17: =H19*1000000/H14 -> 43074.491 | I17: =I19*1000000/I14 -> 42494.204 | J17: =I17*(1+J16) -> 41644.32 | K17: =J17*(1+K16) -> 41019.655 | L17: =K17*(1+L16) -> 40609.459 | M17: =L17*(1+M16) -> 40406.412 | N17: =M17*(1+N16) -> 40406.412 | O17: =N17*(1+O16) -> 40608.444 | P17: =O17*(1+P16) -> 40811.486 | Q17: =P17*(1+Q16) -> 41219.601 | ... T17: =S17*(1+T16) -> 42468.596
C19: Automotive Revenue | G19: 82419 | H19: 77070 | I19: 69526 | J19: =J14*J17/1000000 -> 76993.092 | K19: =K14*K17/1000000 -> 83422.016 | L19: =L14*L17/1000000 -> 90020.697 | M19: =M14*M17/1000000 -> 96736.241 | N19: =N14*N17/1000000 -> 103507.78 | O19: =O14*O17/1000000 -> 110266.84 | P19: =P14*P17/1000000 -> 116913.17 | Q19: =Q14*Q17/1000000 -> 123986.42 | ... T19: =T14*T17/1000000 -> 141628.01
C21: Energy Revenue Growth | H21: =H22/G22-1 -> 0.67125104 | I21: =I22/H22-1 -> 0.26621059 | J21: =Inputs!H28 -> 0.18 | K21: =Inputs!I28 -> 0.33 | L21: =Inputs!J28 -> 0.22 | M21: =Inputs!K28 -> 0.18 | N21: =Inputs!L28 -> 0.15 | O21: =Inputs!M28 -> 0.13 | P21: =Inputs!N28 -> 0.11 | Q21: =Inputs!O28 -> 0.09 | ... T21: =Inputs!R28 -> 0.05
C22: Energy Generation and Storage Revenue | G22: 6035 | H22: 10086 | I22: 12771 | J22: =I22*(1+J21) -> 15069.78 | K22: =J22*(1+K21) -> 20042.807 | L22: =K22*(1+L21) -> 24452.225 | M22: =L22*(1+M21) -> 28853.626 | N22: =M22*(1+N21) -> 33181.669 | O22: =N22*(1+O21) -> 37495.286 | P22: =O22*(1+P21) -> 41619.768 | Q22: =P22*(1+Q21) -> 45365.547 | ... T22: =S22*(1+T21) -> 54026.284
C24: Services and Software Revenue Growth | H24: =H25/G25-1 -> 0.26625796 | I24: =I25/H25-1 -> 0.18948168 | J24: =Inputs!H34 -> 0.3 | K24: =Inputs!I34 -> 0.19 | L24: =Inputs!J34 -> 0.3 | M24: =Inputs!K34 -> 0.28 | N24: =Inputs!L34 -> 0.25 | O24: =Inputs!M34 -> 0.2 | P24: =Inputs!N34 -> 0.16 | Q24: =Inputs!O34 -> 0.13 | ... T24: =Inputs!R34 -> 0.05
C25: Services, Software and Other Revenue | G25: 8319 | H25: 10534 | I25: 12530 | J25: =I25*(1+J24) -> 16289 | K25: =J25*(1+K24) -> 19383.91 | L25: =K25*(1+L24) -> 25199.083 | M25: =L25*(1+M24) -> 32254.826 | N25: =M25*(1+N24) -> 40318.533 | O25: =N25*(1+O24) -> 48382.239 | P25: =O25*(1+P24) -> 56123.398 | Q25: =P25*(1+Q24) -> 63419.439 | ... T25: =S25*(1+T24) -> 79109.409
C27: Total Revenue | G27: =G19+G22+G25 -> 96773 | H27: =H19+H22+H25 -> 97690 | I27: =I19+I22+I25 -> 94827 | J27: =J19+J22+J25 -> 108351.87 | K27: =K19+K22+K25 -> 122848.73 | L27: =L19+L22+L25 -> 139672.01 | M27: =M19+M22+M25 -> 157844.69 | N27: =N19+N22+N25 -> 177007.98 | ... T27: =T19+T22+T25 -> 274763.7
C28: Revenue Growth | H28: =H27/G27-1 -> 0.0094757835 | I28: =I27/H27-1 -> -0.029306992 | J28: =J27/I27-1 -> 0.14262681 | K28: =K27/J27-1 -> 0.13379428 | L28: =L27/K27-1 -> 0.13694298 | M28: =M27/L27-1 -> 0.13010974 | N28: =N27/M27-1 -> 0.12140597 | O28: =O27/N27-1 -> 0.10811028 | ... T28: =T27/S27-1 -> 0.044977616
C30: Memo: Automotive % of Revenue | G30: =G19/G27 -> 0.8516735 | H30: =H19/H27 -> 0.78892415 | I30: =I19/I27 -> 0.73318781 | J30: =J19/J27 -> 0.71058387 | K30: =K19/K27 -> 0.67906289 | L30: =L19/L27 -> 0.64451496 | M30: =M19/M27 -> 0.6128571 | N30: =N19/N27 -> 0.58476334 | ... T30: =T19/T27 -> 0.51545385
C31: Memo: Energy % of Revenue | G31: =G22/G27 -> 0.062362436 | H31: =H22/H27 -> 0.10324496 | I31: =I22/I27 -> 0.13467683 | J31: =J22/J27 -> 0.13908186 | K31: =K22/K27 -> 0.1631503 | L31: =L22/L27 -> 0.17506891 | M31: =M22/M27 -> 0.18279757 | N31: =N22/N27 -> 0.18745861 | ... T31: =T22/T27 -> 0.19662817
C32: Memo: Services and Software % of Revenue | G32: =G25/G27 -> 0.08596406 | H32: =H25/H27 -> 0.10783089 | I32: =I25/I27 -> 0.13213536 | J32: =J25/J27 -> 0.15033427 | K32: =K25/K27 -> 0.15778681 | L32: =L25/L27 -> 0.18041613 | M32: =M25/M27 -> 0.20434533 | N32: =N25/N27 -> 0.22777805 | ... T32: =T25/T27 -> 0.28791798
C34: FY2023-FY2025 actuals per Tesla Q4 and FY2025 Update, Financial Summary, ir.tesla.com.
C36: Cost and Gross Profit Schedule
C38: All figures in USD millions unless stated | G38: 2023 | H38: 2024 | I38: 2025 | J38: =Inputs!H$13 -> 2026 | K38: =Inputs!I$13 -> 2027 | L38: =Inputs!J$13 -> 2028 | M38: =Inputs!K$13 -> 2029 | N38: =Inputs!L$13 -> 2030 | O38: =Inputs!M$13 -> 2031 | P38: =Inputs!N$13 -> 2032 | Q38: =Inputs!O$13 -> 2033 | ... S38: =Inputs!Q$13 -> 2035 | T38: Term
C39: =IF(Inputs!$E$11=1,"Best Case Selected",IF(Inputs!$E$11=2,"Base Case Selected","Worst Case Selected")) -> Base Case Selected
C41: Automotive Gross Margin (excl. D&A) | G41: =1-G42/G19 -> 0.19449399 | H41: =1-H42/H19 -> 0.18420916 | I41: =1-I42/I19 -> 0.1777896 | J41: =Inputs!H40 -> 0.18 | K41: =Inputs!I40 -> 0.19 | L41: =Inputs!J40 -> 0.25 | M41: =Inputs!K40 -> 0.255 | N41: =Inputs!L40 -> 0.26 | O41: =Inputs!M40 -> 0.265 | P41: =Inputs!N40 -> 0.27 | Q41: =Inputs!O40 -> 0.27 | ... T41: =Inputs!R40 -> 0.275
C42: Automotive Cost of Revenues (excl. D&A) | G42: 66389 | H42: 62873 | I42: 57165 | J42: =J19*(1-J41) -> 63134.336 | K42: =K19*(1-K41) -> 67571.833 | L42: =L19*(1-L41) -> 67515.523 | M42: =M19*(1-M41) -> 72068.5 | N42: =N19*(1-N41) -> 76595.756 | O42: =O19*(1-O41) -> 81046.124 | P42: =P19*(1-P41) -> 85346.614 | Q42: =Q19*(1-Q41) -> 90510.084 | ... T42: =T19*(1-T41) -> 102680.3
C43: Automotive Gross Profit (excl. D&A) | G43: =G19-G42 -> 16030 | H43: =H19-H42 -> 14197 | I43: =I19-I42 -> 12361 | J43: =J19-J42 -> 13858.757 | K43: =K19-K42 -> 15850.183 | L43: =L19-L42 -> 22505.174 | M43: =M19-M42 -> 24667.741 | N43: =N19-N42 -> 26912.022 | ... T43: =T19-T42 -> 38947.702
C45: Energy Generation and Storage Gross Margin (excl. D&A) | G45: =1-G46/G22 -> 0.18906379 | H45: =1-H46/H22 -> 0.26174896 | I45: =1-I46/I22 -> 0.29770574 | J45: =Inputs!H46 -> 0.29 | K45: =Inputs!I46 -> 0.29 | L45: =Inputs!J46 -> 0.34 | M45: =Inputs!K46 -> 0.35 | N45: =Inputs!L46 -> 0.35 | O45: =Inputs!M46 -> 0.35 | P45: =Inputs!N46 -> 0.35 | Q45: =Inputs!O46 -> 0.35 | ... T45: =Inputs!R46 -> 0.35
C46: Energy Generation and Storage Cost of Revenues (excl. D&A) | G46: 4894 | H46: 7446 | I46: 8969 | J46: =J22*(1-J45) -> 10699.544 | K46: =K22*(1-K45) -> 14230.393 | L46: =L22*(1-L45) -> 16138.469 | M46: =M22*(1-M45) -> 18754.857 | N46: =N22*(1-N45) -> 21568.085 | O46: =O22*(1-O45) -> 24371.936 | P46: =P22*(1-P45) -> 27052.849 | Q46: =Q22*(1-Q45) -> 29487.606 | ... T46: =T22*(1-T45) -> 35117.084
C47: Energy Generation and Storage Gross Profit (excl. D&A) | G47: =G22-G46 -> 1141 | H47: =H22-H46 -> 2640 | I47: =I22-I46 -> 3802 | J47: =J22-J46 -> 4370.2362 | K47: =K22-K46 -> 5812.4141 | L47: =L22-L46 -> 8313.7565 | M47: =M22-M46 -> 10098.769 | N47: =N22-N46 -> 11613.584 | ... T47: =T22-T46 -> 18909.199
C49: Services and Software Gross Margin (excl. D&A) | G49: =1-G50/G25 -> 0.058781103 | H49: =1-H50/H25 -> 0.058192519 | I49: =1-I50/I25 -> 0.074301676 | J49: =Inputs!H52 -> 0.12 | K49: =Inputs!I52 -> 0.12 | L49: =Inputs!J52 -> 0.26 | M49: =Inputs!K52 -> 0.31 | N49: =Inputs!L52 -> 0.35 | O49: =Inputs!M52 -> 0.38 | P49: =Inputs!N52 -> 0.4 | Q49: =Inputs!O52 -> 0.41 | ... T49: =Inputs!R52 -> 0.42
C50: Services and Software Cost of Revenues (excl. D&A) | G50: 7830 | H50: 9921 | I50: 11599 | J50: =J25*(1-J49) -> 14334.32 | K50: =K25*(1-K49) -> 17057.841 | L50: =L25*(1-L49) -> 18647.321 | M50: =M25*(1-M49) -> 22255.83 | N50: =N25*(1-N49) -> 26207.046 | O50: =O25*(1-O49) -> 29996.988 | P50: =P25*(1-P49) -> 33674.039 | Q50: =Q25*(1-Q49) -> 37417.469 | ... T50: =T25*(1-T49) -> 45883.457
C51: Services and Software Gross Profit (excl. D&A) | G51: =G25-G50 -> 489 | H51: =H25-H50 -> 613 | I51: =I25-I50 -> 931 | J51: =J25-J50 -> 1954.68 | K51: =K25-K50 -> 2326.0692 | L51: =L25-L50 -> 6551.7616 | M51: =M25-M50 -> 9998.9961 | N51: =N25-N50 -> 14111.486 | ... T51: =T25-T50 -> 33225.952
C53: Total Cost of Revenues (excl. D&A) | G53: =G42+G46+G50 -> 79113 | H53: =H42+H46+H50 -> 80240 | I53: =I42+I46+I50 -> 77733 | J53: =J42+J46+J50 -> 88168.2 | K53: =K42+K46+K50 -> 98860.067 | L53: =L42+L46+L50 -> 102301.31 | M53: =M42+M46+M50 -> 113079.19 | N53: =N42+N46+N50 -> 124370.89 | ... T53: =T42+T46+T50 -> 183680.85
C54: Total Gross Profit (excl. D&A) | G54: =G27-G53 -> 17660 | H54: =H27-H53 -> 17450 | I54: =I27-I53 -> 17094 | J54: =J27-J53 -> 20183.673 | K54: =K27-K53 -> 23988.666 | L54: =L27-L53 -> 37370.692 | M54: =M27-M53 -> 44765.507 | N54: =N27-N53 -> 52637.093 | ... T54: =T27-T53 -> 91082.853
C55: Gross Margin (excl. D&A) | G55: =G54/G27 -> 0.18248892 | H55: =H54/H27 -> 0.17862627 | I55: =I54/I27 -> 0.18026511 | J55: =J54/J27 -> 0.18627895 | K55: =K54/K27 -> 0.19526995 | L55: =L54/L27 -> 0.26756036 | M55: =M54/M27 -> 0.28360476 | N55: =N54/N27 -> 0.2973713 | ... T55: =T54/T27 -> 0.33149522
C57: Depreciation and amortisation is presented separately below and has been reallocated out of cost of revenues.
C59: Income Statement
C61: All figures in USD millions unless stated | G61: 2023 | H61: 2024 | I61: 2025 | J61: =Inputs!H$13 -> 2026 | K61: =Inputs!I$13 -> 2027 | L61: =Inputs!J$13 -> 2028 | M61: =Inputs!K$13 -> 2029 | N61: =Inputs!L$13 -> 2030 | O61: =Inputs!M$13 -> 2031 | P61: =Inputs!N$13 -> 2032 | Q61: =Inputs!O$13 -> 2033 | ... S61: =Inputs!Q$13 -> 2035 | T61: Term
C62: =IF(Inputs!$E$11=1,"Best Case Selected",IF(Inputs!$E$11=2,"Base Case Selected","Worst Case Selected")) -> Base Case Selected
C64: Interest Expense | D64: =Inputs!$M$139 -> 350
C65: Marginal Tax Rate | D65: =Inputs!$M$112 -> 0.22
...

Sheet Relative Valuation
C1: AMIR J
D5: Relative Valuation: Peer Group Multiples
D7: All figures in USD millions unless stated. Multiples are on an FY2026 estimated basis.
D8: Peer set selected on business-model comparability: EV manufacturing, exposure to autonomy software, and scale global OEMs.
D10: Peer Company | E10: Basis for Inclusion | F10: EV / Sales | G10: EV / EBITDA | H10: P / E
D12: BYD Company Ltd. | E12: China EV / vertically integrated | F12: 1 | G12: 6.7 | H12: 16
D13: Li Auto Inc. | E13: China EV / premium NEV | F13: 0.2 | G13: 2.5 | H13: 39.1
D14: XPeng Inc. | E14: China EV / ADAS-led | F14: 5.8 | G14: - | H14: -
D15: NIO Inc. | E15: China EV / battery swap | F15: 0.6 | G15: 8.4 | H15: 63.4
D16: Rivian Automotive Inc. | E16: US EV pure play | F16: 2.6 | G16: - | H16: -
D17: Lucid Group Inc. | E17: US EV pure play | F17: 2.5 | G17: - | H17: -
D18: General Motors Co. | E18: US legacy OEM / EV transition | F18: 0.4 | G18: 3.2 | H18: 6.4
D19: Ford Motor Co. | E19: US legacy OEM / EV transition | F19: 2.5 | G19: 3.8 | H19: 8
D21: Peer Mean | F21: =AVERAGE(F12:F19) -> 1.95 | G21: =AVERAGE(G12:G19) -> 4.92 | H21: =AVERAGE(H12:H19) -> 26.58
D22: Peer Median | F22: =MEDIAN(F12:F19) -> 1.75 | G22: =MEDIAN(G12:G19) -> 3.8 | H22: =MEDIAN(H12:H19) -> 16
D24: Tesla, Inc. (at market) | E24: Current trading multiples | F24: =$F$33/Model!$J$27 -> 9.7875734 | G24: =$F$33/Model!$J$256 -> 87.043338 | H24: =Inputs!$G$141/(Model!$J$85/Inputs!$G$140) -> 276.90717
D26: Peer multiples are analyst-compiled estimates and should be refreshed against a live data terminal before publication.
D27: Six of nine peers are loss-making or marginally profitable, so EV/Sales is the only multiple available across the full set.
D28: Implied Valuation from Peer Multiples
D29: Applied to Tesla FY2026 estimated metrics from the operating model, base case (switch = 2).
D31: Metric | E31: FY2026E Tesla Metric | F31: Enterprise Value | G31: Equity Value | H31: Value per Share | I31: Premium / (Discount)
D33: Market Enterprise Value | E33: Current market capitalisation | F33: =Inputs!$G$140*Inputs!$G$141+Inputs!$M$132 -> 1060501.9 | G33: =Inputs!$G$140*Inputs!$G$141 -> 1096184.9 | H33: =Inputs!$G$141 -> 309.22 | I33: 0
D35: Peer Median EV / Sales | E35: =Model!$J$27 -> 108351.87 | F35: =E35*$F$22 -> 189615.78 | G35: =F35-Inputs!$M$132 -> 225298.78 | H35: =G35/Inputs!$G$140 -> 63.553957 | I35: =H35/Inputs!$G$141-1 -> -0.7944701
D36: Peer Median EV / EBITDA | E36: =Model!$J$256 -> 12183.608 | F36: =E36*$G$22 -> 46297.71 | G36: =F36-Inputs!$M$132 -> 81980.71 | H36: =G36/Inputs!$G$140 -> 23.125729 | I36: =H36/Inputs!$G$141-1 -> -0.9252127
D37: Peer Mean EV / Sales | E37: =Model!$J$27 -> 108351.87 | F37: =E37*$F$21 -> 211286.15 | G37: =F37-Inputs!$M$132 -> 246969.15 | H37: =G37/Inputs!$G$140 -> 69.666897 | I37: =H37/Inputs!$G$141-1 -> -0.77470119
D38: Peer Mean EV / EBITDA | E38: =Model!$J$256 -> 12183.608 | F38: =E38*$G$21 -> 59943.351 | G38: =F38-Inputs!$M$132 -> 95626.351 | H38: =G38/Inputs!$G$140 -> 26.974993 | I38: =H38/Inputs!$G$141-1 -> -0.9127644
D40: Growth-Adjusted Premium Applied | E40: 1 | G40: Premium to peer median EV/EBITDA to reflect Tesla's superior growth and software mix.
D41: Premium-Adjusted EV / EBITDA | E41: =Model!$J$256 -> 12183.608 | F41: =E41*$G$22*(1+$E$40) -> 92595.42 | G41: =F41-Inputs!$M$132 -> 128278.42 | H41: =G41/Inputs!$G$140 -> 36.185732 | I41: =H41/Inputs!$G$141-1 -> -0.88297739
D43: Tesla's FY2026E EBITDA is depressed by an elevated investment phase, which flatters the implied EV/EBITDA multiple relative to peers.
D45: Valuation Summary and Recommendation
D48: Methodology | E48: Weighting | F48: Enterprise Value | G48: Equity Value | H48: Value per Share | I48: Premium / (Discount)
D50: DCF - Perpetuity Growth Method | E50: 0.4 | F50: =Model!$I$307 -> 616187.58 | G50: =F50-Inputs!$M$132 -> 651870.58 | H50: =G50/Inputs!$G$140 -> 183.88451 | I50: =H50/Inputs!$G$141-1 -> -0.4053279
D51: DCF - Terminal Multiple Method | E51: 0.35 | F51: =Model!$I$349 -> 589784.74 | G51: =F51-Inputs!$M$132 -> 625467.74 | H51: =G51/Inputs!$G$140 -> 176.4366 | I51: =H51/Inputs!$G$141-1 -> -0.42941401
D52: Relative - Peer Median EV/EBITDA (premium adjusted) | E52: 0.25 | F52: =$F$41 -> 92595.42 | G52: =F52-Inputs!$M$132 -> 128278.42 | H52: =G52/Inputs!$G$140 -> 36.185732 | I52: =H52/Inputs!$G$141-1 -> -0.88297739
D54: Weighted Fair Value | E54: =SUM(E50:E52) -> 1 | F54: =SUMPRODUCT(E50:E52,F50:F52) -> 476048.54 | G54: =F54-Inputs!$M$132 -> 511731.54 | H54: =G54/Inputs!$G$140 -> 144.35305 | I54: =H54/Inputs!$G$141-1 -> -0.53317041
D56: Current Share Price | H56: =Inputs!$G$141 -> 309.22
D58: Recommendation | E58: =IF(H54/Inputs!$G$141-1>0.15,"BUY",IF(H54/Inputs!$G$141-1<-0.15,"SELL","HOLD")) -> SELL | G58: Threshold: BUY above +15%, SELL below -15%, otherwise HOLD.
D64: Valuation Range | H64: =Outputs!$I$18 -> 61.226639
D65: Low (Worst Case, Perpetuity) | H65: =H54 -> 144.35305
D66: Central (Base Case, Weighted) | H66: =Outputs!$I$16 -> 417.31841
...
